<?xml version="1.0"?>
<robot name="armed_walker">
  
  <!-- Materials -->
  <material name="blue"><color rgba="0 0 1 1"/></material>
  <material name="red"><color rgba="1 0 0 1"/></material>
  <material name="green"><color rgba="0 1 0 1"/></material>
  <material name="orange"><color rgba="1 0.5 0 1"/></material>
  <material name="purple"><color rgba="0.5 0 1 1"/></material>
  <material name="yellow"><color rgba="1 1 0 1"/></material>
  
  <!-- HIP (Base) -->
  <link name="hip">
    <inertial>
      <origin xyz="0 0 0" rpy="0 0 0"/>
      <mass value="10.0"/>
      <inertia ixx="0.02" ixy="0" ixz="0" iyy="0.02" iyz="0" izz="0.02"/>
    </inertial>
    <visual>
      <origin xyz="0 0 0" rpy="0 0 0"/>
      <geometry>
        <box size="0.15 0.15 0.1"/>
      </geometry>
      <material name="green"/>
    </visual>
    <collision>
      <origin xyz="0 0 0" rpy="0 0 0"/>
      <geometry>
        <box size="0.15 0.15 0.1"/>
      </geometry>
    </collision>
  </link>
  
  <!-- ================================================================ -->
  <!-- LEG 1 (Right/Stance) - BLUE -->
  <!-- ================================================================ -->
  
  <link name="thigh1">
    <inertial>
      <origin xyz="0 0 -0.225" rpy="0 0 0"/>
      <mass value="7.0"/>
      <inertia ixx="0.1" ixy="0" ixz="0" iyy="0.1" iyz="0" izz="0.001"/>
    </inertial>
    <visual>
      <origin xyz="0 0 -0.225" rpy="0 0 0"/>
      <geometry>
        <cylinder radius="0.025" length="0.45"/>
      </geometry>
      <material name="blue"/>
    </visual>
    <collision>
      <origin xyz="0 0 -0.225" rpy="0 0 0"/>
      <geometry>
        <cylinder radius="0.025" length="0.45"/>
      </geometry>
    </collision>
  </link>
  
  <joint name="hip1" type="continuous">
    <parent link="hip"/>
    <child link="thigh1"/>
    <origin xyz="0 0.06 -0.05" rpy="0 0 0"/>
    <axis xyz="0 1 0"/>
    <dynamics damping="0.02" friction="0.0"/>
  </joint>
  
  <link name="shin1">
    <inertial>
      <origin xyz="0 0 -0.215" rpy="0 0 0"/>
      <mass value="3.5"/>
      <inertia ixx="0.05" ixy="0" ixz="0" iyy="0.05" iyz="0" izz="0.001"/>
    </inertial>
    <visual>
      <origin xyz="0 0 -0.215" rpy="0 0 0"/>
      <geometry>
        <cylinder radius="0.025" length="0.43"/>
      </geometry>
      <material name="blue"/>
    </visual>
    <collision>
      <origin xyz="0 0 -0.215" rpy="0 0 0"/>
      <geometry>
        <cylinder radius="0.025" length="0.43"/>
      </geometry>
    </collision>
  </link>
  
  <joint name="knee1" type="revolute">
    <parent link="thigh1"/>
    <child link="shin1"/>
    <origin xyz="0 0 -0.45" rpy="0 0 0"/>
    <axis xyz="0 1 0"/>
    <limit lower="0.0" upper="1.1344640137963142" effort="0" velocity="10"/>
    <dynamics damping="0.02" friction="0.0"/>
  </joint>
  
  <link name="foot1">
    <inertial>
      <origin xyz="0 0 0" rpy="0 0 0"/>
      <mass value="0.5"/>
      <inertia ixx="0.001" ixy="0" ixz="0" iyy="0.001" iyz="0" izz="0.001"/>
    </inertial>
    <visual>
      <origin xyz="0 0 0" rpy="0 0 0"/>
      <geometry>
        <sphere radius="0.035"/>
      </geometry>
      <material name="red"/>
    </visual>
    <collision>
      <origin xyz="0 0 0" rpy="0 0 0"/>
      <geometry>
        <sphere radius="0.035"/>
      </geometry>
    </collision>
  </link>
  
  <joint name="ankle1" type="fixed">
    <parent link="shin1"/>
    <child link="foot1"/>
    <origin xyz="0 0 -0.43" rpy="0 0 0"/>
  </joint>
  
  <!-- ================================================================ -->
  <!-- LEG 2 (Left/Swing) - ORANGE -->
  <!-- ================================================================ -->
  
  <link name="thigh2">
    <inertial>
      <origin xyz="0 0 -0.225" rpy="0 0 0"/>
      <mass value="7.0"/>
      <inertia ixx="0.1" ixy="0" ixz="0" iyy="0.1" iyz="0" izz="0.001"/>
    </inertial>
    <visual>
      <origin xyz="0 0 -0.225" rpy="0 0 0"/>
      <geometry>
        <cylinder radius="0.025" length="0.45"/>
      </geometry>
      <material name="orange"/>
    </visual>
    <collision>
      <origin xyz="0 0 -0.225" rpy="0 0 0"/>
      <geometry>
        <cylinder radius="0.025" length="0.45"/>
      </geometry>
    </collision>
  </link>
  
  <joint name="hip2" type="continuous">
    <parent link="hip"/>
    <child link="thigh2"/>
    <origin xyz="0 -0.06 -0.05" rpy="0 0 0"/>
    <axis xyz="0 1 0"/>
    <dynamics damping="0.02" friction="0.0"/>
  </joint>
  
  <link name="shin2">
    <inertial>
      <origin xyz="0 0 -0.215" rpy="0 0 0"/>
      <mass value="3.5"/>
      <inertia ixx="0.05" ixy="0" ixz="0" iyy="0.05" iyz="0" izz="0.001"/>
    </inertial>
    <visual>
      <origin xyz="0 0 -0.215" rpy="0 0 0"/>
      <geometry>
        <cylinder radius="0.025" length="0.43"/>
      </geometry>
      <material name="orange"/>
    </visual>
    <collision>
      <origin xyz="0 0 -0.215" rpy="0 0 0"/>
      <geometry>
        <cylinder radius="0.025" length="0.43"/>
      </geometry>
    </collision>
  </link>
  
  <joint name="knee2" type="revolute">
    <parent link="thigh2"/>
    <child link="shin2"/>
    <origin xyz="0 0 -0.45" rpy="0 0 0"/>
    <axis xyz="0 1 0"/>
    <limit lower="0.0" upper="1.1344640137963142" effort="0" velocity="10"/>
    <dynamics damping="0.02" friction="0.0"/>
  </joint>
  
  <link name="foot2">
    <inertial>
      <origin xyz="0 0 0" rpy="0 0 0"/>
      <mass value="0.5"/>
      <inertia ixx="0.001" ixy="0" ixz="0" iyy="0.001" iyz="0" izz="0.001"/>
    </inertial>
    <visual>
      <origin xyz="0 0 0" rpy="0 0 0"/>
      <geometry>
        <sphere radius="0.035"/>
      </geometry>
      <material name="red"/>
    </visual>
    <collision>
      <origin xyz="0 0 0" rpy="0 0 0"/>
      <geometry>
        <sphere radius="0.035"/>
      </geometry>
    </collision>
  </link>
  
  <joint name="ankle2" type="fixed">
    <parent link="shin2"/>
    <child link="foot2"/>
    <origin xyz="0 0 -0.43" rpy="0 0 0"/>
  </joint>
  
  <!-- ================================================================ -->
  <!-- ARM 1 (Right) - PURPLE (Counter-swings with left leg) -->
  <!-- ================================================================ -->
  
  <link name="upper_arm1">
    <inertial>
      <origin xyz="0 0 0.15" rpy="0 0 0"/>
      <mass value="2.0"/>
      <inertia ixx="0.02" ixy="0" ixz="0" iyy="0.02" iyz="0" izz="0.001"/>
    </inertial>
    <visual>
      <origin xyz="0 0 0.15" rpy="0 0 0"/>
      <geometry>
        <cylinder radius="0.02" length="0.3"/>
      </geometry>
      <material name="purple"/>
    </visual>
    <collision>
      <origin xyz="0 0 0.15" rpy="0 0 0"/>
      <geometry>
        <cylinder radius="0.02" length="0.3"/>
      </geometry>
    </collision>
  </link>
  
  <joint name="shoulder1" type="continuous">
    <parent link="hip"/>
    <child link="upper_arm1"/>
    <origin xyz="0 0.12 0.05" rpy="0 0 0"/>
    <axis xyz="0 1 0"/>
    <dynamics damping="0.01" friction="0.0"/>
  </joint>
  
  <link name="forearm1">
    <inertial>
      <origin xyz="0 0 0.125" rpy="0 0 0"/>
      <mass value="1.5"/>
      <inertia ixx="0.01" ixy="0" ixz="0" iyy="0.01" iyz="0" izz="0.001"/>
    </inertial>
    <visual>
      <origin xyz="0 0 0.125" rpy="0 0 0"/>
      <geometry>
        <cylinder radius="0.02" length="0.25"/>
      </geometry>
      <material name="purple"/>
    </visual>
    <collision>
      <origin xyz="0 0 0.125" rpy="0 0 0"/>
      <geometry>
        <cylinder radius="0.02" length="0.25"/>
      </geometry>
    </collision>
  </link>
  
  <joint name="elbow1" type="revolute">
    <parent link="upper_arm1"/>
    <child link="forearm1"/>
    <origin xyz="0 0 0.3" rpy="0 0 0"/>
    <axis xyz="0 1 0"/>
    <limit lower="0.0" upper="1.5707963267948966" effort="0" velocity="10"/>
    <dynamics damping="0.01" friction="0.0"/>
  </joint>
  
  <!-- ================================================================ -->
  <!-- ARM 2 (Left) - YELLOW (Counter-swings with right leg) -->
  <!-- ================================================================ -->
  
  <link name="upper_arm2">
    <inertial>
      <origin xyz="0 0 0.15" rpy="0 0 0"/>
      <mass value="2.0"/>
      <inertia ixx="0.02" ixy="0" ixz="0" iyy="0.02" iyz="0" izz="0.001"/>
    </inertial>
    <visual>
      <origin xyz="0 0 0.15" rpy="0 0 0"/>
      <geometry>
        <cylinder radius="0.02" length="0.3"/>
      </geometry>
      <material name="yellow"/>
    </visual>
    <collision>
      <origin xyz="0 0 0.15" rpy="0 0 0"/>
      <geometry>
        <cylinder radius="0.02" length="0.3"/>
      </geometry>
    </collision>
  </link>
  
  <joint name="shoulder2" type="continuous">
    <parent link="hip"/>
    <child link="upper_arm2"/>
    <origin xyz="0 -0.12 0.05" rpy="0 0 0"/>
    <axis xyz="0 1 0"/>
    <dynamics damping="0.01" friction="0.0"/>
  </joint>
  
  <link name="forearm2">
    <inertial>
      <origin xyz="0 0 0.125" rpy="0 0 0"/>
      <mass value="1.5"/>
      <inertia ixx="0.01" ixy="0" ixz="0" iyy="0.01" iyz="0" izz="0.001"/>
    </inertial>
    <visual>
      <origin xyz="0 0 0.125" rpy="0 0 0"/>
      <geometry>
        <cylinder radius="0.02" length="0.25"/>
      </geometry>
      <material name="yellow"/>
    </visual>
    <collision>
      <origin xyz="0 0 0.125" rpy="0 0 0"/>
      <geometry>
        <cylinder radius="0.02" length="0.25"/>
      </geometry>
    </collision>
  </link>
  
  <joint name="elbow2" type="revolute">
    <parent link="upper_arm2"/>
    <child link="forearm2"/>
    <origin xyz="0 0 0.3" rpy="0 0 0"/>
    <axis xyz="0 1 0"/>
    <limit lower="0.0" upper="1.5707963267948966" effort="0" velocity="10"/>
    <dynamics damping="0.01" friction="0.0"/>
  </joint>
  
</robot>
